Workbook

Sheet SPY
B2: AUM-cierre 2017 | C2: 158789.66 | D2: =C2 -> 158789.66
B3: 43132 | C3: -6144.012 | D3: =D2+C3 -> 152645.65 | E3: =LN(D3/D2) -> -0.039461224
B4: 43160 | C4: -1048.214 | D4: =D3+C4 -> 151597.43 | E4: =LN(D4/D3) -> -0.0068906622
B5: 43191 | C5: -1677.034 | D5: =D4+C5 -> 149920.4 | E5: =LN(D5/D4) -> -0.01112406
B6: 43221 | C6: -624.76 | D6: =D5+C6 -> 149295.64 | E6: =LN(D6/D5) -> -0.0041759854
B7: 43313 | C7: -1559.184 | D7: =D6+C7 -> 147736.46 | E7: =LN(D7/D6) -> -0.010498517
B8: 43344 | C8: 2438.595 | D8: =D7+C8 -> 150175.05 | E8: =LN(D8/D7) -> 0.016371637
B9: 43374 | C9: -1152.643 | D9: =D8+C9 -> 149022.41 | E9: =LN(D9/D8) -> -0.0077049364
B10: 43405 | C10: 3618.606 | D10: =D9+C10 -> 152641.01 | E10: =LN(D10/D9) -> 0.023992167
B11: 43435 | C11: 2898.89 | D11: =D10+C11 -> 155539.9 | E11: =LN(D11/D10) -> 0.018813465
B12: 01/16/2018 | C12: -1598.182 | D12: =D11+C12 -> 153941.72 | E12: =LN(D12/D11) -> -0.010328214
B13: 01/17/2018 | C13: -235.425 | D13: =D12+C13 -> 153706.3 | E13: =LN(D13/D12) -> -0.0015304831
B14: 01/18/2018 | C14: 6709.774 | D14: =D13+C14 -> 160416.07 | E14: =LN(D14/D13) -> 0.042727265
B15: 01/19/2018 | C15: -1116.589 | D15: =D14+C15 -> 159299.48 | E15: =LN(D15/D14) -> -0.0069849185
B16: 01/22/2018 | C16: 3168.24 | D16: =D15+C16 -> 162467.72 | E16: =LN(D16/D15) -> 0.019693383
B17: 01/23/2018 | C17: 2458.949 | D17: =D16+C17 -> 164926.67 | E17: =LN(D17/D16) -> 0.015021609
B18: 01/24/2018 | C18: 2450.212 | D18: =D17+C18 -> 167376.88 | E18: =LN(D18/D17) -> 0.014747097
B19: 01/25/2018 | C19: -750.224 | D19: =D18+C19 -> 166626.66 | E19: =LN(D19/D18) -> -0.0044923192
B20: 01/26/2018 | C20: 382.419 | D20: =D19+C20 -> 167009.08 | E20: =LN(D20/D19) -> 0.0022924353
B21: 01/29/2018 | C21: -3066.908 | D21: =D20+C21 -> 163942.17 | E21: =LN(D21/D20) -> -0.018534427
B22: 01/30/2018 | C22: 4299.243 | D22: =D21+C22 -> 168241.41 | E22: =LN(D22/D21) -> 0.025886186
B23: 01/31/2018 | C23: 4140.071 | D23: =D22+C23 -> 172381.48 | E23: =LN(D23/D22) -> 0.024310021
B24: 43102 | C24: 84.534 | D24: =D23+C24 -> 172466.02 | E24: =LN(D24/D23) -> 0.00049026889
B25: 43133 | C25: -2225.065 | D25: =D24+C25 -> 170240.95 | E25: =LN(D25/D24) -> -0.012985416
B26: 43222 | C26: -1847.234 | D26: =D25+C26 -> 168393.72 | E26: =LN(D26/D25) -> -0.010910001
B27: 43253 | C27: -5328.248 | D27: =D26+C27 -> 163065.47 | E27: =LN(D27/D26) -> -0.03215302
B28: 43283 | C28: -7991.108 | D28: =D27+C28 -> 155074.36 | E28: =LN(D28/D27) -> -0.05024702
B29: 43314 | C29: -66.932 | D29: =D28+C29 -> 155007.43 | E29: =LN(D29/D28) -> -0.00043170546
B30: 43345 | C30: -7886.689 | D30: =D29+C30 -> 147120.74 | E30: =LN(D30/D29) -> -0.052219434
B31: 43436 | C31: -2367.989 | D31: =D30+C31 -> 144752.75 | E31: =LN(D31/D30) -> -0.016226489
B32: 02/13/2018 | C32: 7242.567 | D32: =D31+C32 -> 151995.32 | E32: =LN(D32/D31) -> 0.048822596
B33: 02/14/2018 | C33: -997.505 | D33: =D32+C33 -> 150997.82 | E33: =LN(D33/D32) -> -0.0065843644
B34: 02/15/2018 | C34: -808.903 | D34: =D33+C34 -> 150188.91 | E34: =LN(D34/D33) -> -0.0053714515
B35: 02/16/2018 | C35: 518.592 | D35: =D34+C35 -> 150707.5 | E35: =LN(D35/D34) -> 0.0034469837
B36: 02/20/2018 | C36: -3235.845 | D36: =D35+C36 -> 147471.66 | E36: =LN(D36/D35) -> -0.021704884
B37: 02/21/2018 | C37: -665.163 | D37: =D36+C37 -> 146806.5 | E37: =LN(D37/D36) -> -0.0045206491
B38: 02/22/2018 | C38: 2119.605 | D38: =D37+C38 -> 148926.1 | E38: =LN(D38/D37) -> 0.014334851
B39: 02/23/2018 | C39: -108.119 | D39: =D38+C39 -> 148817.98 | E39: =LN(D39/D38) -> -0.0007262546
B40: 02/26/2018 | C40: -2979.72 | D40: =D39+C40 -> 145838.26 | E40: =LN(D40/D39) -> -0.020225749
B41: 02/27/2018 | C41: 5029.629 | D41: =D40+C41 -> 150867.89 | E41: =LN(D41/D40) -> 0.033906347
...

Sheet IVV
B1: AUM-cierre 2017 | C1: 89826.39 | D1: 89826.39
B2: 43132 | C2: -40.276 | D2: =C1+C2 -> 89786.114 | E2: =LN(D2/D1) -> -0.00044847658
B3: 43160 | C3: 703.932 | D3: =D2+C3 -> 90490.046 | E3: =LN(D3/D2) -> 0.0078095249
B4: 43191 | C4: 395.089 | D4: =D3+C4 -> 90885.135 | E4: =LN(D4/D3) -> 0.0043566008
B5: 43221 | C5: -68.407 | D5: =D4+C5 -> 90816.728 | E5: =LN(D5/D4) -> -0.00075295874
B6: 43313 | C6: -13.778 | D6: =D5+C6 -> 90802.95 | E6: =LN(D6/D5) -> -0.00015172365
B7: 43344 | C7: 0 | D7: =D6+C7 -> 90802.95 | E7: =LN(D7/D6) -> 0
B8: 43374 | C8: 2266.947 | D8: =D7+C8 -> 93069.897 | E8: =LN(D8/D7) -> 0.024659017
B9: 43405 | C9: 179.498 | D9: =D8+C9 -> 93249.395 | E9: =LN(D9/D8) -> 0.0019267791
B10: 43435 | C10: 13.906 | D10: =D9+C10 -> 93263.301 | E10: =LN(D10/D9) -> 0.00014911585
B11: 01/16/2018 | C11: 97.998 | D11: =D10+C11 -> 93361.299 | E11: =LN(D11/D10) -> 0.0010502153
B12: 01/17/2018 | C12: -41.852 | D12: =D11+C12 -> 93319.447 | E12: =LN(D12/D11) -> -0.00044838047
B13: 01/18/2018 | C13: 42.245 | D13: =D12+C13 -> 93361.692 | E13: =LN(D13/D12) -> 0.00045258992
B14: 01/19/2018 | C14: -112.482 | D14: =D13+C14 -> 93249.21 | E14: =LN(D14/D13) -> -0.0012055246
B15: 01/22/2018 | C15: -84.734 | D15: =D14+C15 -> 93164.476 | E15: =LN(D15/D14) -> -0.0009090964
B16: 01/23/2018 | C16: 0 | D16: =D15+C16 -> 93164.476 | E16: =LN(D16/D15) -> 0
B17: 01/24/2018 | C17: 28.536 | D17: =D16+C17 -> 93193.012 | E17: =LN(D17/D16) -> 0.00030625011
B18: 01/25/2018 | C18: 228.159 | D18: =D17+C18 -> 93421.171 | E18: =LN(D18/D17) -> 0.0024452494
B19: 01/26/2018 | C19: -28.537 | D19: =D18+C19 -> 93392.634 | E19: =LN(D19/D18) -> -0.00030551276
B20: 01/29/2018 | C20: 2194.529 | D20: =D19+C20 -> 95587.163 | E20: =LN(D20/D19) -> 0.023226056
B21: 01/30/2018 | C21: 387.215 | D21: =D20+C21 -> 95974.378 | E21: =LN(D21/D20) -> 0.0040427272
B22: 01/31/2018 | C22: 226.976 | D22: =D21+C22 -> 96201.354 | E22: =LN(D22/D21) -> 0.0023621724
B23: 43102 | C23: 752.245 | D23: =D22+C23 -> 96953.599 | E23: =LN(D23/D22) -> 0.0077890708
B24: 43133 | C24: 453.977 | D24: =D23+C24 -> 97407.576 | E24: =LN(D24/D23) -> 0.0046714867
B25: 43222 | C25: 708.22 | D25: =D24+C25 -> 98115.796 | E25: =LN(D25/D24) -> 0.007244383
B26: 43253 | C26: 532.682 | D26: =D25+C26 -> 98648.478 | E26: =LN(D26/D25) -> 0.0054144311
B27: 43283 | C27: 271.028 | D27: =D26+C27 -> 98919.506 | E27: =LN(D27/D26) -> 0.0027436446
B28: 43314 | C28: -107.87 | D28: =D27+C28 -> 98811.636 | E28: =LN(D28/D27) -> -0.0010910776
B29: 43345 | C29: -298.542 | D29: =D28+C29 -> 98513.094 | E29: =LN(D29/D28) -> -0.0030258977
B30: 43436 | C30: 237.202 | D30: =D29+C30 -> 98750.296 | E30: =LN(D30/D29) -> 0.0024049279
B31: 02/13/2018 | C31: 307.32 | D31: =D30+C31 -> 99057.616 | E31: =LN(D31/D30) -> 0.0031072594
B32: 02/14/2018 | C32: 428.716 | D32: =D31+C32 -> 99486.332 | E32: =LN(D32/D31) -> 0.0043186072
B33: 02/15/2018 | C33: -122.227 | D33: =D32+C33 -> 99364.105 | E33: =LN(D33/D32) -> -0.0012293362
B34: 02/16/2018 | C34: 0 | D34: =D33+C34 -> 99364.105 | E34: =LN(D34/D33) -> 0
B35: 02/20/2018 | C35: -247.579 | D35: =D34+C35 -> 99116.526 | E35: =LN(D35/D34) -> -0.0024947435
B36: 02/21/2018 | C36: 41.024 | D36: =D35+C36 -> 99157.55 | E36: =LN(D36/D35) -> 0.00041381104
B37: 02/22/2018 | C37: 231.199 | D37: =D36+C37 -> 99388.749 | E37: =LN(D37/D36) -> 0.0023289188
B38: 02/23/2018 | C38: 340.363 | D38: =D37+C38 -> 99729.112 | E38: =LN(D38/D37) -> 0.0034187122
B39: 02/26/2018 | C39: 207.502 | D39: =D38+C39 -> 99936.614 | E39: =LN(D39/D38) -> 0.0020784947
B40: 02/27/2018 | C40: 97.984 | D40: =D39+C40 -> 100034.6 | E40: =LN(D40/D39) -> 0.00097998114
...

Sheet VOO
B2: AUM-cierre 2017 | C2: 61574.97 | D2: 61574.97
B3: 43132 | C3: -36.667 | D3: =C2+C3 -> 61538.303 | E3: =LN(D3/D2) -> -0.00059566284
B4: 43160 | C4: 111.359 | D4: =D3+C4 -> 61649.662 | E4: =LN(D4/D3) -> 0.0018079531
B5: 43191 | C5: 180.218 | D5: =D4+C5 -> 61829.88 | E5: =LN(D5/D4) -> 0.0029189957
B6: 43221 | C6: 108.197 | D6: =D5+C6 -> 61938.077 | E6: =LN(D6/D5) -> 0.0017483851
B7: 43313 | C7: 183.714 | D7: =D6+C7 -> 62121.791 | E7: =LN(D7/D6) -> 0.0029617013
B8: 43344 | C8: 39.067 | D8: =D7+C8 -> 62160.858 | E8: =LN(D8/D7) -> 0.00062867989
B9: 43374 | C9: 202.8 | D9: =D8+C9 -> 62363.658 | E9: =LN(D9/D8) -> 0.0032571928
B10: 43405 | C10: 101.693 | D10: =D9+C10 -> 62465.351 | E10: =LN(D10/D9) -> 0.0016293171
B11: 43435 | C11: 63.492 | D11: =D10+C11 -> 62528.843 | E11: =LN(D11/D10) -> 0.0010159193
B12: 01/16/2018 | C12: 12.996 | D12: =D11+C12 -> 62541.839 | E12: =LN(D12/D11) -> 0.00020781849
B13: 01/17/2018 | C13: 77.019 | D13: =D12+C13 -> 62618.858 | E13: =LN(D13/D12) -> 0.001230722
B14: 01/18/2018 | C14: -44.342 | D14: =D13+C14 -> 62574.516 | E14: =LN(D14/D13) -> -0.00070837618
B15: 01/19/2018 | C15: 26.854 | D15: =D14+C15 -> 62601.37 | E15: =LN(D15/D14) -> 0.00042906028
B16: 01/22/2018 | C16: 413.336 | D16: =D15+C16 -> 63014.706 | E16: =LN(D16/D15) -> 0.0065809649
B17: 01/23/2018 | C17: 130.898 | D17: =D16+C17 -> 63145.604 | E17: =LN(D17/D16) -> 0.0020751066
B18: 01/24/2018 | C18: 130.737 | D18: =D17+C18 -> 63276.341 | E18: =LN(D18/D17) -> 0.0020682651
B19: 01/25/2018 | C19: 97.683 | D19: =D18+C19 -> 63374.024 | E19: =LN(D19/D18) -> 0.001542562
B20: 01/26/2018 | C20: -97.159 | D20: =D19+C20 -> 63276.865 | E20: =LN(D20/D19) -> -0.0015342809
B21: 01/29/2018 | C21: 20.273 | D21: =D20+C21 -> 63297.138 | E21: =LN(D21/D20) -> 0.00032033435
B22: 01/30/2018 | C22: 366.511 | D22: =D21+C22 -> 63663.649 | E22: =LN(D22/D21) -> 0.0057736255
B23: 01/31/2018 | C23: 388.711 | D23: =D22+C23 -> 64052.36 | E23: =LN(D23/D22) -> 0.0060871335
B24: 43102 | C24: -94.487 | D24: =D23+C24 -> 63957.873 | E24: =LN(D24/D23) -> -0.0014762416
B25: 43133 | C25: 187.813 | D25: =D24+C25 -> 64145.686 | E25: =LN(D25/D24) -> 0.0029322079
B26: 43222 | C26: -113.257 | D26: =D25+C26 -> 64032.429 | E26: =LN(D26/D25) -> -0.001767182
B27: 43253 | C27: -498.003 | D27: =D26+C27 -> 63534.426 | E27: =LN(D27/D26) -> -0.0078077574
B28: 43283 | C28: 153.982 | D28: =D27+C28 -> 63688.408 | E28: =LN(D28/D27) -> 0.0024206673
B29: 43314 | C29: 106.427 | D29: =D28+C29 -> 63794.835 | E29: =LN(D29/D28) -> 0.001669663
B30: 43345 | C30: 148.097 | D30: =D29+C30 -> 63942.932 | E30: =LN(D30/D29) -> 0.0023187671
B31: 43436 | C31: 146.617 | D31: =D30+C31 -> 64089.549 | E31: =LN(D31/D30) -> 0.0022903104
B32: 02/13/2018 | C32: 135.114 | D32: =D31+C32 -> 64224.663 | E32: =LN(D32/D31) -> 0.0021059873
B33: 02/14/2018 | C33: 223.192 | D33: =D32+C33 -> 64447.855 | E33: =LN(D33/D32) -> 0.0034691514
B34: 02/15/2018 | C34: 198.539 | D34: =D33+C34 -> 64646.394 | E34: =LN(D34/D33) -> 0.0030758792
B35: 02/16/2018 | C35: 128.487 | D35: =D34+C35 -> 64774.881 | E35: =LN(D35/D34) -> 0.0019855629
B36: 02/20/2018 | C36: 37.855 | D36: =D35+C36 -> 64812.736 | E36: =LN(D36/D35) -> 0.00058423794
B37: 02/21/2018 | C37: 362.395 | D37: =D36+C37 -> 65175.131 | E37: =LN(D37/D36) -> 0.0055758425
B38: 02/22/2018 | C38: -24.632 | D38: =D37+C38 -> 65150.499 | E38: =LN(D38/D37) -> -0.000378007
B39: 02/23/2018 | C39: 132.864 | D39: =D38+C39 -> 65283.363 | E39: =LN(D39/D38) -> 0.0020372631
B40: 02/26/2018 | C40: 152.054 | D40: =D39+C40 -> 65435.417 | E40: =LN(D40/D39) -> 0.0023264303
B41: 02/27/2018 | C41: 58.229 | D41: =D40+C41 -> 65493.646 | E41: =LN(D41/D40) -> 0.00088947408
...

Sheet Agregado
B1: date | C1: total_net_flows_SPY | D1: total_net_flows_IVV | E1: total_net_flows_VOO | F1: total | G1: variación
C2: 158789.66 | D2: 89826.39 | E2: 61574.97 | F2: =SUM(C2:E2) -> 310191.02 | I2: Inicio Semana | J2: 43112 | K2: 0.03028 | M2: 43102 | N2: 268.77 | O2: 43132 | P2: {=XLOOKUP(O2,Agregado!$B$2:$B$1511,Agregado!$G$2:$G$1511)} -> #N/A
B3: 2 / 1 / 2018 | C3: 152645.65 | D3: 89786.114 | E3: 61538.303 | F3: =SUM(C3:E3) -> 303970.07 | G3: =LN(F3/F2) -> -0.020259075 | I3: 43105 | J3: 43119 | K3: 0.01218 | M3: 43103 | N3: 270.47 | O3: 43160 | P3: {=XLOOKUP(O3,Agregado!$B$2:$B$1511,Agregado!$G$2:$G$1511)} -> #N/A
B4: 3 / 1 / 2018 | C4: 151597.43 | D4: 90490.046 | E4: 61649.662 | F4: =SUM(C4:E4) -> 303737.14 | G4: =LN(F4/F3) -> -0.00076656327 | I4: 43112 | J4: 43126 | K4: 0.02669 | M4: 43104 | N4: 271.61 | O4: 43191 | P4: {=XLOOKUP(O4,Agregado!$B$2:$B$1511,Agregado!$G$2:$G$1511)} -> #N/A
B5: 4 / 1 / 2018 | C5: 149920.4 | D5: 90885.135 | E5: 61829.88 | F5: =SUM(C5:E5) -> 302635.41 | G5: =LN(F5/F4) -> -0.0036338327 | I5: 43119 | J5: 43133 | K5: 0.02476 | M5: 43105 | N5: 273.42 | O5: 43221 | P5: {=XLOOKUP(O5,Agregado!$B$2:$B$1511,Agregado!$G$2:$G$1511)} -> #N/A
B6: 5 / 1 / 2018 | C6: 149295.64 | D6: 90816.728 | E6: 61938.077 | F6: =SUM(C6:E6) -> 302050.45 | G6: =LN(F6/F5) -> -0.0019347903 | I6: 43126 | J6: 43140 | K6: -0.06931 | M6: 43108 | N6: 273.92 | O6: 43313 | P6: {=XLOOKUP(O6,Agregado!$B$2:$B$1511,Agregado!$G$2:$G$1511)} -> #N/A
B7: 8 / 1 / 2018 | C7: 147736.46 | D7: 90802.95 | E7: 62121.791 | F7: =SUM(C7:E7) -> 300661.2 | G7: =LN(F7/F6) -> -0.0046100004 | I7: 43133 | J7: 43147 | K7: 0.01688 | M7: 43109 | N7: 274.54 | O7: 43344 | P7: {=XLOOKUP(O7,Agregado!$B$2:$B$1511,Agregado!$G$2:$G$1511)} -> #N/A
B8: 9 / 1 / 2018 | C8: 150175.05 | D8: 90802.95 | E8: 62160.858 | F8: =SUM(C8:E8) -> 303138.86 | G8: =LN(F8/F7) -> 0.0082069416 | I8: 43140 | J8: 43154 | K8: -0.00323 | M8: 43110 | N8: 274.12 | O8: 43374 | P8: {=XLOOKUP(O8,Agregado!$B$2:$B$1511,Agregado!$G$2:$G$1511)} -> #N/A
B9: 10 / 1 / 2018 | C9: 149022.41 | D9: 93069.897 | E9: 62363.658 | F9: =SUM(C9:E9) -> 304455.96 | G9: =LN(F9/F8) -> 0.0043354749 | I9: 43147 | J9: 43161 | K9: 0.00855 | M9: 43111 | N9: 276.12 | O9: 43405 | P9: {=XLOOKUP(O9,Agregado!$B$2:$B$1511,Agregado!$G$2:$G$1511)} -> #N/A
B10: 11 / 1 / 2018 | C10: 152641.01 | D10: 93249.395 | E10: 62465.351 | F10: =SUM(C10:E10) -> 308355.76 | G10: =LN(F10/F9) -> 0.012727725 | I10: 43154 | J10: 43168 | K10: -0.0171 | M10: 43112 | N10: 277.92 | O10: 43435 | P10: {=XLOOKUP(O10,Agregado!$B$2:$B$1511,Agregado!$G$2:$G$1511)} -> #N/A
B11: 12 / 1 / 2018 | C11: 155539.9 | D11: 93263.301 | E11: 62528.843 | F11: =SUM(C11:E11) -> 311332.05 | G11: =LN(F11/F10) -> 0.0096058397 | I11: 43161 | J11: 43175 | K11: 0.01057 | M11: 43116 | N11: 276.97 | O11: 01/16/2018 | P11: {=XLOOKUP(O11,Agregado!$B$2:$B$1511,Agregado!$G$2:$G$1511)} -> #N/A
B12: 16 / 1 / 2018 | C12: 153941.72 | D12: 93361.299 | E12: 62541.839 | F12: =SUM(C12:E12) -> 309844.86 | G12: =LN(F12/F11) -> -0.0047883005 | I12: 43168 | J12: 43182 | K12: -0.0376 | M12: 43117 | N12: 279.61 | O12: 01/17/2018 | P12: {=XLOOKUP(O12,Agregado!$B$2:$B$1511,Agregado!$G$2:$G$1511)} -> #N/A
B13: 17 / 1 / 2018 | C13: 153706.3 | D13: 93319.447 | E13: 62618.858 | F13: =SUM(C13:E13) -> 309644.6 | G13: =LN(F13/F12) -> -0.00064652595 | I13: 43175 | J13: 43188 | K13: -0.01929 | M13: 43118 | N13: 279.14 | O13: 01/18/2018 | P13: {=XLOOKUP(O13,Agregado!$B$2:$B$1511,Agregado!$G$2:$G$1511)} -> #N/A
B14: 18 / 1 / 2018 | C14: 160416.07 | D14: 93361.692 | E14: 62574.516 | F14: =SUM(C14:E14) -> 316352.28 | G14: =LN(F14/F13) -> 0.021431205 | I14: 43182 | J14: 43196 | K14: -0.0168 | M14: 43119 | N14: 280.41 | O14: 01/19/2018 | P14: {=XLOOKUP(O14,Agregado!$B$2:$B$1511,Agregado!$G$2:$G$1511)} -> #N/A
B15: 19 / 1 / 2018 | C15: 159299.48 | D15: 93249.21 | E15: 62601.37 | F15: =SUM(C15:E15) -> 315150.06 | G15: =LN(F15/F14) -> -0.0038074869 | I15: 43188 | J15: 43203 | K15: 0.00799 | M15: 43122 | N15: 282.69 | O15: 01/22/2018 | P15: {=XLOOKUP(O15,Agregado!$B$2:$B$1511,Agregado!$G$2:$G$1511)} -> #N/A
B16: 22 / 1 / 2018 | C16: 162467.72 | D16: 93164.476 | E16: 63014.706 | F16: =SUM(C16:E16) -> 318646.9 | G16: =LN(F16/F15) -> 0.011034693 | I16: 43196 | J16: 43210 | K16: 0.00237 | M16: 43123 | N16: 283.29 | O16: 01/23/2018 | P16: {=XLOOKUP(O16,Agregado!$B$2:$B$1511,Agregado!$G$2:$G$1511)} -> #N/A
B17: 23 / 1 / 2018 | C17: 164926.67 | D17: 93164.476 | E17: 63145.604 | F17: =SUM(C17:E17) -> 321236.75 | G17: =LN(F17/F16) -> 0.0080947876 | I17: 43203 | J17: 43217 | K17: 0.00746 | M17: 43124 | N17: 283.18 | O17: 01/24/2018 | P17: {=XLOOKUP(O17,Agregado!$B$2:$B$1511,Agregado!$G$2:$G$1511)} -> #N/A
B18: 24 / 1 / 2018 | C18: 167376.88 | D18: 93193.012 | E18: 63276.341 | F18: =SUM(C18:E18) -> 323846.24 | G18: =LN(F18/F17) -> 0.0080904296 | I18: 43210 | J18: 43224 | K18: -0.00498 | M18: 43125 | N18: 283.3 | O18: 01/25/2018 | P18: {=XLOOKUP(O18,Agregado!$B$2:$B$1511,Agregado!$G$2:$G$1511)} -> #N/A
B19: 25 / 1 / 2018 | C19: 166626.66 | D19: 93421.171 | E19: 63374.024 | F19: =SUM(C19:E19) -> 323421.85 | G19: =LN(F19/F18) -> -0.0013113023 | I19: 43217 | J19: 43231 | K19: 0.02403 | M19: 43126 | N19: 286.58 | O19: 01/26/2018 | P19: {=XLOOKUP(O19,Agregado!$B$2:$B$1511,Agregado!$G$2:$G$1511)} -> #N/A
B20: 26 / 1 / 2018 | C20: 167009.08 | D20: 93392.634 | E20: 63276.865 | F20: =SUM(C20:E20) -> 323678.58 | G20: =LN(F20/F19) -> 0.00079345647 | I20: 43224 | J20: 43238 | K20: 0.00911 | M20: 43129 | N20: 284.68 | O20: 01/29/2018 | P20: {=XLOOKUP(O20,Agregado!$B$2:$B$1511,Agregado!$G$2:$G$1511)} -> #N/A
B21: 29 / 1 / 2018 | C21: 163942.17 | D21: 95587.163 | E21: 63297.138 | F21: =SUM(C21:E21) -> 322826.47 | G21: =LN(F21/F20) -> -0.0026360397 | I21: 43231 | J21: 43245 | K21: 0.01083 | M21: 43130 | N21: 281.76 | O21: 01/30/2018 | P21: {=XLOOKUP(O21,Agregado!$B$2:$B$1511,Agregado!$G$2:$G$1511)} -> #N/A
B22: 30 / 1 / 2018 | C22: 168241.41 | D22: 95974.378 | E22: 63663.649 | F22: =SUM(C22:E22) -> 327879.44 | G22: =LN(F22/F21) -> 0.015531042 | I22: 43238 | J22: 43252 | K22: -0.01065 | M22: 43131 | N22: 281.9 | O22: 01/31/2018 | P22: {=XLOOKUP(O22,Agregado!$B$2:$B$1511,Agregado!$G$2:$G$1511)} -> #N/A
B23: 31 / 1 / 2018 | C23: 172381.48 | D23: 96201.354 | E23: 64052.36 | F23: =SUM(C23:E23) -> 332635.2 | G23: =LN(F23/F22) -> 0.014400408 | I23: 43245 | J23: 43259 | K23: -0.00393 | M23: 43132 | N23: 281.58 | O23: 43102 | P23: {=XLOOKUP(O23,Agregado!$B$2:$B$1511,Agregado!$G$2:$G$1511)} -> #N/A
B24: 1 / 2 / 2018 | C24: 172466.02 | D24: 96953.599 | E24: 63957.873 | F24: =SUM(C24:E24) -> 333377.49 | G24: =LN(F24/F23) -> 0.0022290636 | I24: 43252 | J24: 43266 | K24: -0.01401 | M24: 43133 | N24: 275.45 | O24: 43133 | P24: {=XLOOKUP(O24,Agregado!$B$2:$B$1511,Agregado!$G$2:$G$1511)} -> #N/A
B25: 2 / 2 / 2018 | C25: 170240.95 | D25: 97407.576 | E25: 64145.686 | F25: =SUM(C25:E25) -> 331794.22 | G25: =LN(F25/F24) -> -0.0047605091 | I25: 43259 | J25: 43273 | K25: 0.00799 | M25: 43136 | N25: 263.93 | O25: 43222 | P25: {=XLOOKUP(O25,Agregado!$B$2:$B$1511,Agregado!$G$2:$G$1511)} -> #N/A
B26: 5 / 2 / 2018 | C26: 168393.72 | D26: 98115.796 | E26: 64032.429 | F26: =SUM(C26:E26) -> 330541.94 | G26: =LN(F26/F25) -> -0.0037813804 | I26: 43266 | J26: 43280 | K26: -0.01055 | M26: 43137 | N26: 269.13 | O26: 43253 | P26: {=XLOOKUP(O26,Agregado!$B$2:$B$1511,Agregado!$G$2:$G$1511)} -> #N/A
B27: 6 / 2 / 2018 | C27: 163065.47 | D27: 98648.478 | E27: 63534.426 | F27: =SUM(C27:E27) -> 325248.38 | G27: =LN(F27/F26) -> -0.016144441 | I27: 43273 | J27: 43287 | K27: -0.00518 | M27: 43138 | N27: 267.67 | O27: 43283 | P27: {=XLOOKUP(O27,Agregado!$B$2:$B$1511,Agregado!$G$2:$G$1511)} -> #N/A
B28: 7 / 2 / 2018 | C28: 155074.36 | D28: 98919.506 | E28: 63688.408 | F28: =SUM(C28:E28) -> 317682.28 | G28: =LN(F28/F27) -> -0.023537367 | I28: 43280 | J28: 43294 | K28: 0.00194 | M28: 43139 | N28: 257.63 | O28: 43314 | P28: {=XLOOKUP(O28,Agregado!$B$2:$B$1511,Agregado!$G$2:$G$1511)} -> #N/A
B29: 8 / 2 / 2018 | C29: 155007.43 | D29: 98811.636 | E29: 63794.835 | F29: =SUM(C29:E29) -> 317613.9 | G29: =LN(F29/F28) -> -0.00021525393 | I29: 43287 | J29: 43301 | K29: -0.00224 | M29: 43140 | N29: 261.5 | O29: 43345 | P29: {=XLOOKUP(O29,Agregado!$B$2:$B$1511,Agregado!$G$2:$G$1511)} -> #N/A
B30: 9 / 2 / 2018 | C30: 147120.74 | D30: 98513.094 | E30: 63942.932 | F30: =SUM(C30:E30) -> 309576.77 | G30: =LN(F30/F29) -> -0.0256304 | I30: 43294 | J30: 43308 | K30: 0.00768 | M30: 43143 | N30: 265.34 | O30: 43436 | P30: {=XLOOKUP(O30,Agregado!$B$2:$B$1511,Agregado!$G$2:$G$1511)} -> #N/A
B31: 12 / 2 / 2018 | C31: 144752.75 | D31: 98750.296 | E31: 64089.549 | F31: =SUM(C31:E31) -> 307592.6 | G31: =LN(F31/F30) -> -0.0064299265 | I31: 43301 | J31: 43315 | K31: -0.00952 | M31: 43144 | N31: 266 | O31: 02/13/2018 | P31: {=XLOOKUP(O31,Agregado!$B$2:$B$1511,Agregado!$G$2:$G$1511)} -> #N/A
B32: 13 / 2 / 2018 | C32: 151995.32 | D32: 99057.616 | E32: 64224.663 | F32: =SUM(C32:E32) -> 315277.6 | G32: =LN(F32/F31) -> 0.024677344 | I32: 43308 | J32: 43322 | K32: 0.0233 | M32: 43145 | N32: 269.59 | O32: 02/14/2018 | P32: {=XLOOKUP(O32,Agregado!$B$2:$B$1511,Agregado!$G$2:$G$1511)} -> #N/A
B33: 14 / 2 / 2018 | C33: 150997.81 | D33: 99486.332 | E33: 64447.855 | F33: =SUM(C33:E33) -> 314932 | G33: =LN(F33/F32) -> -0.0010967685 | I33: 43315 | J33: 43329 | K33: 0.00026 | M33: 43146 | N33: 273.03 | O33: 02/15/2018 | P33: {=XLOOKUP(O33,Agregado!$B$2:$B$1511,Agregado!$G$2:$G$1511)} -> #N/A
B34: 15 / 2 / 2018 | C34: 150188.91 | D34: 99364.105 | E34: 64646.394 | F34: =SUM(C34:E34) -> 314199.41 | G34: =LN(F34/F33) -> -0.0023288976 | I34: 43322 | J34: 43336 | K34: -0.0044 | M34: 43147 | N34: 273.11 | O34: 02/16/2018 | P34: {=XLOOKUP(O34,Agregado!$B$2:$B$1511,Agregado!$G$2:$G$1511)} -> #N/A
B35: 16 / 2 / 2018 | C35: 150707.5 | D35: 99364.105 | E35: 64774.881 | F35: =SUM(C35:E35) -> 314846.49 | G35: =LN(F35/F34) -> 0.0020573355 | I35: 43329 | J35: 43343 | K35: 0.00683 | M35: 43151 | N35: 271.4 | O35: 02/20/2018 | P35: {=XLOOKUP(O35,Agregado!$B$2:$B$1511,Agregado!$G$2:$G$1511)} -> #N/A
B36: 20 / 2 / 2018 | C36: 147471.66 | D36: 99116.526 | E36: 64812.736 | F36: =SUM(C36:E36) -> 311400.92 | G36: =LN(F36/F35) -> -0.01100397 | I36: 43336 | J36: 43350 | K36: 0.0016 | M36: 43152 | N36: 270.05 | O36: 02/21/2018 | P36: {=XLOOKUP(O36,Agregado!$B$2:$B$1511,Agregado!$G$2:$G$1511)} -> #N/A
B37: 21 / 2 / 2018 | C37: 146806.5 | D37: 99157.55 | E37: 65175.131 | F37: =SUM(C37:E37) -> 311139.18 | G37: =LN(F37/F36) -> -0.00084089046 | I37: 43343 | J37: 43357 | K37: -0.00302 | M37: 43153 | N37: 270.4 | O37: 02/22/2018 | P37: {=XLOOKUP(O37,Agregado!$B$2:$B$1511,Agregado!$G$2:$G$1511)} -> #N/A
B38: 22 / 2 / 2018 | C38: 148926.1 | D38: 99388.749 | E38: 65150.499 | F38: =SUM(C38:E38) -> 313465.35 | G38: =LN(F38/F37) -> 0.0074484979 | I38: 43350 | J38: 43364 | K38: 0.04855 | M38: 43154 | N38: 274.71 | O38: 02/23/2018 | P38: {=XLOOKUP(O38,Agregado!$B$2:$B$1511,Agregado!$G$2:$G$1511)} -> #N/A
B39: 23 / 2 / 2018 | C39: 148817.98 | D39: 99729.112 | E39: 65283.363 | F39: =SUM(C39:E39) -> 313830.46 | G39: =LN(F39/F38) -> 0.0011640698 | I39: 43357 | J39: 43371 | K39: -0.01494 | M39: 43157 | N39: 277.9 | O39: 02/26/2018 | P39: {=XLOOKUP(O39,Agregado!$B$2:$B$1511,Agregado!$G$2:$G$1511)} -> #N/A
B40: 26 / 2 / 2018 | C40: 145838.26 | D40: 99936.614 | E40: 65435.417 | F40: =SUM(C40:E40) -> 311210.29 | G40: =LN(F40/F39) -> -0.0083840273 | I40: 43364 | J40: 43378 | K40: 0.01524 | M40: 43158 | N40: 274.43 | O40: 02/27/2018 | P40: {=XLOOKUP(O40,Agregado!$B$2:$B$1511,Agregado!$G$2:$G$1511)} -> #N/A
...

Sheet Hoja5
A2: 43102 | B2: 268.77 | C2: 43132 | D2: {=XLOOKUP(Hoja5!A2,#REF!,Agregado!G2:G1511)} -> #REF!
A3: 43103 | B3: 270.47 | C3: 43160 | D3: {=XLOOKUP(Hoja5!A3,#REF!,Agregado!G3:G1511)} -> #REF!
A4: 43104 | B4: 271.61 | C4: 43191 | D4: {=XLOOKUP(Hoja5!A4,Agregado!B1512,Agregado!G4:G1512)} -> #N/A
A5: 43105 | B5: 273.42 | C5: 43221 | D5: {=XLOOKUP(Hoja5!A5,Agregado!B1512:B1513,Agregado!G5:G1513)} -> #N/A
A6: 43108 | B6: 273.92 | C6: 43313 | D6: {=XLOOKUP(Hoja5!A6,Agregado!B1512:B1514,Agregado!G6:G1514)} -> #N/A
A7: 43109 | B7: 274.54 | C7: 43344 | D7: {=XLOOKUP(Hoja5!A7,Agregado!B1512:B1515,Agregado!G7:G1515)} -> #N/A
A8: 43110 | B8: 274.12 | C8: 43374 | D8: {=XLOOKUP(Hoja5!A8,Agregado!B1512:B1516,Agregado!G8:G1516)} -> #N/A
A9: 43111 | B9: 276.12 | C9: 43405 | D9: {=XLOOKUP(Hoja5!A9,Agregado!B1512:B1517,Agregado!G9:G1517)} -> #N/A
A10: 43112 | B10: 277.92 | C10: 43435 | D10: {=XLOOKUP(Hoja5!A10,Agregado!B1512:B1518,Agregado!G10:G1518)} -> #N/A
A11: 43116 | B11: 276.97 | C11: 01/16/2018 | D11: {=XLOOKUP(Hoja5!A11,Agregado!B1512:B1519,Agregado!G11:G1519)} -> #N/A
A12: 43117 | B12: 279.61 | C12: 01/17/2018 | D12: {=XLOOKUP(Hoja5!A12,Agregado!B1512:B1520,Agregado!G12:G1520)} -> #N/A
A13: 43118 | B13: 279.14 | C13: 01/18/2018 | D13: {=XLOOKUP(Hoja5!A13,Agregado!B1512:B1521,Agregado!G13:G1521)} -> #N/A
A14: 43119 | B14: 280.41 | C14: 01/19/2018 | D14: {=XLOOKUP(Hoja5!A14,Agregado!B1512:B1522,Agregado!G14:G1522)} -> #N/A
A15: 43122 | B15: 282.69 | C15: 01/22/2018 | D15: {=XLOOKUP(Hoja5!A15,Agregado!B1512:B1523,Agregado!G15:G1523)} -> #N/A
A16: 43123 | B16: 283.29 | C16: 01/23/2018 | D16: {=XLOOKUP(Hoja5!A16,Agregado!B1512:B1524,Agregado!G16:G1524)} -> #N/A
A17: 43124 | B17: 283.18 | C17: 01/24/2018 | D17: {=XLOOKUP(Hoja5!A17,Agregado!B1512:B1525,Agregado!G17:G1525)} -> #N/A
A18: 43125 | B18: 283.3 | C18: 01/25/2018 | D18: {=XLOOKUP(Hoja5!A18,Agregado!B1512:B1526,Agregado!G18:G1526)} -> #N/A
A19: 43126 | B19: 286.58 | C19: 01/26/2018 | D19: {=XLOOKUP(Hoja5!A19,Agregado!B1512:B1527,Agregado!G19:G1527)} -> #N/A
A20: 43129 | B20: 284.68 | C20: 01/29/2018 | D20: {=XLOOKUP(Hoja5!A20,Agregado!B1512:B1528,Agregado!G20:G1528)} -> #N/A
A21: 43130 | B21: 281.76 | C21: 01/30/2018 | D21: {=XLOOKUP(Hoja5!A21,Agregado!B1512:B1529,Agregado!G21:G1529)} -> #N/A
A22: 43131 | B22: 281.9 | C22: 01/31/2018 | D22: {=XLOOKUP(Hoja5!A22,Agregado!B1512:B1530,Agregado!G22:G1530)} -> #N/A
A23: 43132 | B23: 281.58 | C23: 43102 | D23: {=XLOOKUP(Hoja5!A23,Agregado!B1512:B1531,Agregado!G23:G1531)} -> #N/A
A24: 43133 | B24: 275.45 | C24: 43133 | D24: {=XLOOKUP(Hoja5!A24,Agregado!B1512:B1532,Agregado!G24:G1532)} -> #N/A
A25: 43136 | B25: 263.93 | C25: 43222 | D25: {=XLOOKUP(Hoja5!A25,Agregado!B1512:B1533,Agregado!G25:G1533)} -> #N/A
A26: 43137 | B26: 269.13 | C26: 43253 | D26: {=XLOOKUP(Hoja5!A26,Agregado!B1512:B1534,Agregado!G26:G1534)} -> #N/A
A27: 43138 | B27: 267.67 | C27: 43283 | D27: {=XLOOKUP(Hoja5!A27,Agregado!B1512:B1535,Agregado!G27:G1535)} -> #N/A
A28: 43139 | B28: 257.63 | C28: 43314 | D28: {=XLOOKUP(Hoja5!A28,Agregado!B1512:B1536,Agregado!G28:G1536)} -> #N/A
A29: 43140 | B29: 261.5 | C29: 43345 | D29: {=XLOOKUP(Hoja5!A29,Agregado!B1512:B1537,Agregado!G29:G1537)} -> #N/A
A30: 43143 | B30: 265.34 | C30: 43436 | D30: {=XLOOKUP(Hoja5!A30,Agregado!B1512:B1538,Agregado!G30:G1538)} -> #N/A
A31: 43144 | B31: 266 | C31: 02/13/2018 | D31: {=XLOOKUP(Hoja5!A31,Agregado!B1512:B1539,Agregado!G31:G1539)} -> #N/A
A32: 43145 | B32: 269.59 | C32: 02/14/2018 | D32: {=XLOOKUP(Hoja5!A32,Agregado!B1512:B1540,Agregado!G32:G1540)} -> #N/A
A33: 43146 | B33: 273.03 | C33: 02/15/2018 | D33: {=XLOOKUP(Hoja5!A33,Agregado!B1512:B1541,Agregado!G33:G1541)} -> #N/A
A34: 43147 | B34: 273.11 | C34: 02/16/2018 | D34: {=XLOOKUP(Hoja5!A34,Agregado!B1512:B1542,Agregado!G34:G1542)} -> #N/A
A35: 43151 | B35: 271.4 | C35: 02/20/2018 | D35: {=XLOOKUP(Hoja5!A35,Agregado!B1512:B1543,Agregado!G35:G1543)} -> #N/A
A36: 43152 | B36: 270.05 | C36: 02/21/2018 | D36: {=XLOOKUP(Hoja5!A36,Agregado!B1512:B1544,Agregado!G36:G1544)} -> #N/A
A37: 43153 | B37: 270.4 | C37: 02/22/2018 | D37: {=XLOOKUP(Hoja5!A37,Agregado!B1512:B1545,Agregado!G37:G1545)} -> #N/A
A38: 43154 | B38: 274.71 | C38: 02/23/2018 | D38: {=XLOOKUP(Hoja5!A38,Agregado!B1512:B1546,Agregado!G38:G1546)} -> #N/A
A39: 43157 | B39: 277.9 | C39: 02/26/2018 | D39: {=XLOOKUP(Hoja5!A39,Agregado!B1512:B1547,Agregado!G39:G1547)} -> #N/A
A40: 43158 | B40: 274.43 | C40: 02/27/2018 | D40: {=XLOOKUP(Hoja5!A40,Agregado!B1512:B1548,Agregado!G40:G1548)} -> #N/A
A41: 43159 | B41: 271.65 | C41: 02/28/2018 | D41: {=XLOOKUP(Hoja5!A41,Agregado!B1512:B1549,Agregado!G41:G1549)} -> #N/A
...

Sheet Hoja6
A2: 43102 | B2: 268.77 | D2: -0.020259075
A3: 43103 | B3: 270.47 | C3: =LN(B3/B2) -> 0.0063051911 | D3: -0.00076656327 | F3: =CORREL(C3:C1516,D3:D1516) -> -0.0076432568
A4: 43104 | B4: 271.61 | C4: =LN(B4/B3) -> 0.0042060275 | D4: -0.0036338327
A5: 43105 | B5: 273.42 | C5: =LN(B5/B4) -> 0.0066418606 | D5: -0.0019347903
A6: 43108 | B6: 273.92 | C6: =LN(B6/B5) -> 0.0018270185 | D6: -0.0046100004
A7: 43109 | B7: 274.54 | C7: =LN(B7/B6) -> 0.0022608769 | D7: 0.0082069416
A8: 43110 | B8: 274.12 | C8: =LN(B8/B7) -> -0.0015310031 | D8: 0.0043354749
A9: 43111 | B9: 276.12 | C9: =LN(B9/B8) -> 0.0072695871 | D9: 0.012727725
A10: 43112 | B10: 277.92 | C10: =LN(B10/B9) -> 0.0064977487 | D10: 0.0096058397
A11: 43116 | B11: 276.97 | C11: =LN(B11/B10) -> -0.0034241054 | D11: -0.0047883005
A12: 43117 | B12: 279.61 | C12: =LN(B12/B11) -> 0.009486578 | D12: -0.00064652595
A13: 43118 | B13: 279.14 | C13: =LN(B13/B12) -> -0.001682327 | D13: 0.021431205
A14: 43119 | B14: 280.41 | C14: =LN(B14/B13) -> 0.0045393698 | D14: -0.0038074869
A15: 43122 | B15: 282.69 | C15: =LN(B15/B14) -> 0.008098073 | D15: 0.011034693
... A1130: 44729 | B1130: 365.86 | C1130: =LN(B1130/B1129) -> -0.002156968 | D1130: 0.0065884653
A1131: 44002 | C1131: 0 | D1131: 0
A1132: 44733 | B1132: 375.07 | C1132: =LN(B1132/B1130) -> 0.024861929 | D1132: 0.0028357488
A1133: 44734 | B1133: 374.39 | C1133: =LN(B1133/B1132) -> -0.0018146404 | D1133: -0.0096521009
A1134: 44735 | B1134: 378.06 | C1134: =LN(B1134/B1133) -> 0.0097548783 | D1134: 0.0016135252
A1135: 44736 | B1135: 390.08 | C1135: =LN(B1135/B1134) -> 0.031298933 | D1135: -0.0039605548
A1136: 44739 | B1136: 388.59 | C1136: =LN(B1136/B1135) -> -0.0038270431 | D1136: 0.0041696459
A1137: 44740 | B1137: 380.65 | C1137: =LN(B1137/B1136) -> -0.020644485 | D1137: 0.00027597203
A1138: 44741 | B1138: 380.34 | C1138: =LN(B1138/B1137) -> -0.00081472823 | D1138: 0.0021454856
A1139: 44742 | B1139: 377.25 | C1139: =LN(B1139/B1138) -> -0.0081574919 | D1139: -0.0012866126
A1140: 44743 | B1140: 381.24 | C1140: =LN(B1140/B1139) -> 0.010521 | D1140: -0.0011521605
A1141: 44747 | B1141: 381.96 | C1141: =LN(B1141/B1140) -> 0.001886793 | D1141: 0.00039388546
A1142: 44748 | B1142: 383.25 | C1142: =LN(B1142/B1141) -> 0.0033716267 | D1142: -0.0052560462
A1143: 44749 | B1143: 388.99 | C1143: =LN(B1143/B1142) -> 0.014866119 | D1143: 0.0057256726
A1144: 44750 | B1144: 388.67 | C1144: =LN(B1144/B1143) -> -0.00082298181 | D1144: -0.0031306448
... A1381: 45093 | B1381: 439.46 | C1381: =LN(B1381/B1380) -> -0.0071197271 | D1381: 0.00016743251
A1382: 45096 | C1382: 0 | D1382: 0
A1383: 45097 | B1383: 437.18 | C1383: =LN(B1383/B1381) -> -0.0052016909 | D1383: -0.0020199201
A1384: 45098 | B1384: 434.94 | C1384: =LN(B1384/B1383) -> -0.0051369191 | D1384: 0.0075035691
A1385: 45099 | B1385: 436.51 | C1385: =LN(B1385/B1384) -> 0.003603194 | D1385: 0.0061216952
A1386: 45100 | B1386: 433.21 | C1386: =LN(B1386/B1385) -> -0.0075886856 | D1386: -0.0097521678
A1387: 45103 | B1387: 431.44 | C1387: =LN(B1387/B1386) -> -0.0040941479 | D1387: 0.0087434133
A1388: 45104 | B1388: 436.17 | C1388: =LN(B1388/B1387) -> 0.010903625 | D1388: 0.0028900506
A1389: 45105 | B1389: 436.39 | C1389: =LN(B1389/B1388) -> 0.00050426333 | D1389: 0.0058283748
A1390: 45106 | B1390: 438.11 | C1390: =LN(B1390/B1389) -> 0.0039336815 | D1390: 0.004312824
A1391: 45107 | B1391: 443.28 | C1391: =LN(B1391/B1390) -> 0.011731604 | D1391: 0.010593785
...

Sheet Hoja7
B2: 20180102 | C2: 0.85 | D2: 0.35 | E2: -0.22 | F2: 0.006
B3: 20180103 | C3: 0.59 | D3: -0.39 | E3: -0.18 | F3: 0.006
B4: 20180104 | C4: 0.42 | D4: -0.26 | E4: 0.24 | F4: 0.006
B5: 20180105 | C5: 0.66 | D5: -0.35 | E5: -0.26 | F5: 0.006
B6: 20180108 | C6: 0.19 | D6: -0.15 | E6: 0.05 | F6: 0.006
B7: 20180109 | C7: 0.15 | D7: -0.35 | E7: -0.04 | F7: 0.006
B8: 20180110 | C8: -0.07 | D8: 0.07 | E8: 0.57 | F8: 0.006
B9: 20180111 | C9: 0.87 | D9: 1.15 | E9: 0.31 | F9: 0.006
B10: 20180112 | C10: 0.66 | D10: -0.31 | E10: 0.16 | F10: 0.006
B11: 20180116 | C11: -0.49 | D11: -1.02 | E11: 0.01 | F11: 0.006
B12: 20180117 | C12: 0.95 | D12: -0.03 | E12: -0.10 | F12: 0.006
B13: 20180118 | C13: -0.18 | D13: -0.50 | E13: -0.25 | F13: 0.006
... B1510: 20231229 | C1510: -0.43 | D1510: -1.13 | E1510: -0.37 | F1510: 0.021
